Workbook
Name NativeTimeline_End_Date_Clean: #N/A
Name NativeTimeline_Join_Date_Clean: #N/A
Name Slicer_Experience_Years: #N/A
Name Slicer_Salary: #N/A
Name Slicer_Salary_Range: #N/A
Name Slicer_Status_Clean: #N/A

Sheet Messy_Data
A1: Emp ID | B1: Emp ID Clean | C1: Emp Name | D1: Emp Name Clean | E1: Department | F1: Department Clean | G1: Join Date | H1: Join Date Clean | I1: End Date | J1: End Date Clean | K1: Mobile No | L1: Mobile No Clean | M1: Email | N1: Email Clean | O1: Salary | P1: Salary Range | Q1: Salary Range Count | R1: Manager ID | S1: Manager ID Clean | T1: Status | U1: Status Clean | V1: Experience Days | W1: Experience Months | X1: Experience Years | Y1: Total Resigned | Z1: Avg Exp Resi Emp Years | AA1: High Salary & Low Exp Audit
A2: EMP1 | B2: =TRIM(UPPER(A2)) -> EMP1 | C2: ravi | D2: =PROPER(TRIM(C2)) -> Ravi | E2: IT | F2: =TRIM(UPPER(E2)) -> IT | G2: 2022/01/17 | H2: =DATEVALUE(G2) -> 44578 | I2: 2025/03/04 | J2: =IF(I2="",TODAY(),DATEVALUE(I2)) -> 45720 | K2: 9878481087 | L2: =VALUE(K2) -> 9878481087 | M2: Amit@company.com | N2: =TRIM(LOWER(M2)) -> amit@company.com | O2: 16661 | P2: =IF(O2<20000,"Below 20K", IF(O2<=40000,"20K-40K", IF(O2<=60000,"40K-60K", IF(O2<=80000,"60K-80K", "Above 80K")))) -> Below 20K | Q2: Below 20K | R2: M4 | S2: =TRIM(CLEAN(SUBSTITUTE(R2," ",""))) -> M4 | T2: RESIGNED | U2: =TRIM(UPPER(T2)) -> RESIGNED | V2: =DATEDIF(H2,J2,"D") -> 1142 | W2: =DATEDIF(H2,J2,"M") -> 37 | X2: =DATEDIF(H2,J2,"Y") -> 3 | Y2: =COUNTIF($U:$U,"RESIGNED") -> 120 | Z2: =AVERAGEIF(U:U,"RESIGNED",X:X) -> 1.9166667 | AA2: =IF(AND(O2>80000,X2<2),"CHECK","OK") -> OK
A3: EMP2 | B3: =TRIM(UPPER(A3)) -> EMP2 | C3: ravi | D3: =PROPER(TRIM(C3)) -> Ravi | E3: Finance | F3: =TRIM(UPPER(E3)) -> FINANCE | G3: 2023/08/13 | H3: =DATEVALUE(G3) -> 45151 | I3: 2023/11/15 | J3: =IF(I3="",TODAY(),DATEVALUE(I3)) -> 45245 | K3: 9377218497 | L3: =VALUE(K3) -> 9377218497 | M3: Pooja@company.com | N3: =TRIM(LOWER(M3)) -> pooja@company.com | O3: 66881 | P3: =IF(O3<20000,"Below 20K", IF(O3<=40000,"20K-40K", IF(O3<=60000,"40K-60K", IF(O3<=80000,"60K-80K", "Above 80K")))) -> 60K-80K | Q3: =COUNTIF($P:$P,"Below 20k") -> 38 | R3: M8 | S3: =TRIM(CLEAN(SUBSTITUTE(R3," ",""))) -> M8 | T3: RESIGNED | U3: =TRIM(UPPER(T3)) -> RESIGNED | V3: =DATEDIF(H3,J3,"D") -> 94 | W3: =DATEDIF(H3,J3,"M") -> 3 | X3: =DATEDIF(H3,J3,"Y") -> 0 | AA3: =IF(AND(O3>80000,X3<2),"CHECK","OK") -> OK
A4: EMP3 | B4: =TRIM(UPPER(A4)) -> EMP3 | C4: ankit | D4: =PROPER(TRIM(C4)) -> Ankit | E4: HR | F4: =TRIM(UPPER(E4)) -> HR | G4: 25-11-2022 | H4: =DATEVALUE(G4) -> 44890 | I4: 2023/03/12 | J4: =IF(I4="",TODAY(),DATEVALUE(I4)) -> 44997 | K4: 9595920356 | L4: =VALUE(K4) -> 9595920356 | M4: SURESH@company.com | N4: =TRIM(LOWER(M4)) -> suresh@company.com | O4: 86913 | P4: =IF(O4<20000,"Below 20K", IF(O4<=40000,"20K-40K", IF(O4<=60000,"40K-60K", IF(O4<=80000,"60K-80K", "Above 80K")))) -> Above 80K | R4: M3 | S4: =TRIM(CLEAN(SUBSTITUTE(R4," ",""))) -> M3 | T4: On Hold | U4: =TRIM(UPPER(T4)) -> ON HOLD | V4: =DATEDIF(H4,J4,"D") -> 107 | W4: =DATEDIF(H4,J4,"M") -> 3 | X4: =DATEDIF(H4,J4,"Y") -> 0 | Y4: Total Active | Z4: Avg Exp Active Emp Months | AA4: =IF(AND(O4>80000,X4<2),"CHECK","OK") -> CHECK
A5: emp4 | B5: =TRIM(UPPER(A5)) -> EMP4 | C5: ravi | D5: =PROPER(TRIM(C5)) -> Ravi | E5: it | F5: =TRIM(UPPER(E5)) -> IT | G5: 2020/09/14 | H5: =DATEVALUE(G5) -> 44088 | I5: 2022/02/06 | J5: =IF(I5="",TODAY(),DATEVALUE(I5)) -> 44598 | K5: 9941224943 | L5: =VALUE(K5) -> 9941224943 | M5: neha@company.com | N5: =TRIM(LOWER(M5)) -> neha@company.com | O5: 33885 | P5: =IF(O5<20000,"Below 20K", IF(O5<=40000,"20K-40K", IF(O5<=60000,"40K-60K", IF(O5<=80000,"60K-80K", "Above 80K")))) -> 20K-40K | Q5: 20K-40K | R5: M8 | S5: =TRIM(CLEAN(SUBSTITUTE(R5," ",""))) -> M8 | T5: Active | U5: =TRIM(UPPER(T5)) -> ACTIVE | V5: =DATEDIF(H5,J5,"D") -> 510 | W5: =DATEDIF(H5,J5,"M") -> 16 | X5: =DATEDIF(H5,J5,"Y") -> 1 | Y5: =COUNTIF($U:$U,"ACTIVE") -> 105 | Z5: =AVERAGEIF(U:U,"ACTIVE",W:W) -> 29.066667 | AA5: =IF(AND(O5>80000,X5<2),"CHECK","OK") -> OK
A6: EMP5 | B6: =TRIM(UPPER(A6)) -> EMP5 | C6: Amit | D6: =PROPER(TRIM(C6)) -> Amit | E6: Sales | F6: =TRIM(UPPER(E6)) -> SALES | G6: 2021/11/16 | H6: =DATEVALUE(G6) -> 44516 | I6: 20-08-2025 | J6: =IF(I6="",TODAY(),DATEVALUE(I6)) -> 45889 | K6: 9245370465 | L6: =VALUE(K6) -> 9245370465 | M6: ravi@company.com | N6: =TRIM(LOWER(M6)) -> ravi@company.com | O6: 94504 | P6: =IF(O6<20000,"Below 20K", IF(O6<=40000,"20K-40K", IF(O6<=60000,"40K-60K", IF(O6<=80000,"60K-80K", "Above 80K")))) -> Above 80K | Q6: =COUNTIF($P:$P,"20K-40K") -> 76 | R6: M9 | S6: =TRIM(CLEAN(SUBSTITUTE(R6," ",""))) -> M9 | T6: resigned | U6: =TRIM(UPPER(T6)) -> RESIGNED | V6: =DATEDIF(H6,J6,"D") -> 1373 | W6: =DATEDIF(H6,J6,"M") -> 45 | X6: =DATEDIF(H6,J6,"Y") -> 3 | AA6: =IF(AND(O6>80000,X6<2),"CHECK","OK") -> OK
A7: EMP6 | B7: =TRIM(UPPER(A7)) -> EMP6 | C7: Sunita | D7: =PROPER(TRIM(C7)) -> Sunita | E7: finance | F7: =TRIM(UPPER(E7)) -> FINANCE | G7: 06-10-2019 | H7: =DATEVALUE(G7) -> 43744 | I7: 2020/03/08 | J7: =IF(I7="",TODAY(),DATEVALUE(I7)) -> 43898 | K7: 9349938125 | L7: =VALUE(K7) -> 9349938125 | M7: KIRAN@company.com | N7: =TRIM(LOWER(M7)) -> kiran@company.com | O7: 49791 | P7: =IF(O7<20000,"Below 20K", IF(O7<=40000,"20K-40K", IF(O7<=60000,"40K-60K", IF(O7<=80000,"60K-80K", "Above 80K")))) -> 40K-60K | R7: M16 | S7: =TRIM(CLEAN(SUBSTITUTE(R7," ",""))) -> M16 | T7: RESIGNED | U7: =TRIM(UPPER(T7)) -> RESIGNED | V7: =DATEDIF(H7,J7,"D") -> 154 | W7: =DATEDIF(H7,J7,"M") -> 5 | X7: =DATEDIF(H7,J7,"Y") -> 0 | Y7: Total On Hold | Z7: Highest 1st Salary Option 1 | AA7: =IF(AND(O7>80000,X7<2),"CHECK","OK") -> OK
A8: EMP7 | B8: =TRIM(UPPER(A8)) -> EMP7 | C8: ravi | D8: =PROPER(TRIM(C8)) -> Ravi | E8: Finance | F8: =TRIM(UPPER(E8)) -> FINANCE | G8: 2021/01/18 | H8: =DATEVALUE(G8) -> 44214 | J8: =IF(I8="",TODAY(),DATEVALUE(I8)) -> 46024 | K8: 9900001110 | L8: =VALUE(K8) -> 9900001110 | M8: KIRAN@company.com | N8: =TRIM(LOWER(M8)) -> kiran@company.com | O8: 86686 | P8: =IF(O8<20000,"Below 20K", IF(O8<=40000,"20K-40K", IF(O8<=60000,"40K-60K", IF(O8<=80000,"60K-80K", "Above 80K")))) -> Above 80K | Q8: 40K-60K | R8: M2 | S8: =TRIM(CLEAN(SUBSTITUTE(R8," ",""))) -> M2 | T8: resigned | U8: =TRIM(UPPER(T8)) -> RESIGNED | V8: =DATEDIF(H8,J8,"D") -> 1810 | W8: =DATEDIF(H8,J8,"M") -> 59 | X8: =DATEDIF(H8,J8,"Y") -> 4 | Y8: =COUNTIF($U:$U,"ON HOLD") -> 75 | Z8: =LARGE(O:O,1) -> 94569 | AA8: =IF(AND(O8>80000,X8<2),"CHECK","OK") -> OK
A9: emp8 | B9: =TRIM(UPPER(A9)) -> EMP8 | C9: Sunita | D9: =PROPER(TRIM(C9)) -> Sunita | E9: hr | F9: =TRIM(UPPER(E9)) -> HR | G9: 2022/06/14 | H9: =DATEVALUE(G9) -> 44726 | I9: 2026/02/08 | J9: =IF(I9="",TODAY(),DATEVALUE(I9)) -> 46061 | K9: 9125742616 | L9: =VALUE(K9) -> 9125742616 | M9: Pooja@gmail.com | N9: =TRIM(LOWER(M9)) -> pooja@gmail.com | O9: 37975 | P9: =IF(O9<20000,"Below 20K", IF(O9<=40000,"20K-40K", IF(O9<=60000,"40K-60K", IF(O9<=80000,"60K-80K", "Above 80K")))) -> 20K-40K | Q9: =COUNTIF($P:$P,"40K-60K") -> 66 | R9: M13 | S9: =TRIM(CLEAN(SUBSTITUTE(R9," ",""))) -> M13 | T9: Active | U9: =TRIM(UPPER(T9)) -> ACTIVE | V9: =DATEDIF(H9,J9,"D") -> 1335 | W9: =DATEDIF(H9,J9,"M") -> 43 | X9: =DATEDIF(H9,J9,"Y") -> 3 | AA9: =IF(AND(O9>80000,X9<2),"CHECK","OK") -> OK
A10: EMP9 | B10: =TRIM(UPPER(A10)) -> EMP9 | C10: Pooja | D10: =PROPER(TRIM(C10)) -> Pooja | E10: it | F10: =TRIM(UPPER(E10)) -> IT | G10: 02-02-2023 | H10: =DATEVALUE(G10) -> 44959 | I10: 2025/07/06 | J10: =IF(I10="",TODAY(),DATEVALUE(I10)) -> 45844 | K10: 9188103283 | L10: =VALUE(K10) -> 9188103283 | M10: neha@company.com | N10: =TRIM(LOWER(M10)) -> neha@company.com | O10: 18480 | P10: =IF(O10<20000,"Below 20K", IF(O10<=40000,"20K-40K", IF(O10<=60000,"40K-60K", IF(O10<=80000,"60K-80K", "Above 80K")))) -> Below 20K | R10: M 13 | S10: =TRIM(CLEAN(SUBSTITUTE(R10," ",""))) -> M13 | T10: RESIGNED | U10: =TRIM(UPPER(T10)) -> RESIGNED | V10: =DATEDIF(H10,J10,"D") -> 885 | W10: =DATEDIF(H10,J10,"M") -> 29 | X10: =DATEDIF(H10,J10,"Y") -> 2 | Z10: Highest 5th Salary Option 2 | AA10: =IF(AND(O10>80000,X10<2),"CHECK","OK") -> OK
A11: EMP10 | B11: =TRIM(UPPER(A11)) -> EMP10 | C11: ravi | D11: =PROPER(TRIM(C11)) -> Ravi | E11: it | F11: =TRIM(UPPER(E11)) -> IT | G11: 2021/08/16 | H11: =DATEVALUE(G11) -> 44424 | I11: 10-04-2023 | J11: =IF(I11="",TODAY(),DATEVALUE(I11)) -> 45026 | K11: 9526289266 | L11: =VALUE(K11) -> 9526289266 | M11: Sunita@company.com | N11: =TRIM(LOWER(M11)) -> sunita@company.com | O11: 72669 | P11: =IF(O11<20000,"Below 20K", IF(O11<=40000,"20K-40K", IF(O11<=60000,"40K-60K", IF(O11<=80000,"60K-80K", "Above 80K")))) -> 60K-80K | Q11: 60K-80K | R11: M14 | S11: =TRIM(CLEAN(SUBSTITUTE(R11," ",""))) -> M14 | T11: On Hold | U11: =TRIM(UPPER(T11)) -> ON HOLD | V11: =DATEDIF(H11,J11,"D") -> 602 | W11: =DATEDIF(H11,J11,"M") -> 19 | X11: =DATEDIF(H11,J11,"Y") -> 1 | Z11: =LARGE(O:O,5) -> 94195 | AA11: =IF(AND(O11>80000,X11<2),"CHECK","OK") -> OK
A12: EMP11 | B12: =TRIM(UPPER(A12)) -> EMP11 | C12: Sunita | D12: =PROPER(TRIM(C12)) -> Sunita | E12: hr | F12: =TRIM(UPPER(E12)) -> HR | G12: 2019/02/01 | H12: =DATEVALUE(G12) -> 43497 | I12: 2019/08/07 | J12: =IF(I12="",TODAY(),DATEVALUE(I12)) -> 43684 | K12: 9302136537 | L12: =VALUE(K12) -> 9302136537 | M12: neha@company.com | N12: =TRIM(LOWER(M12)) -> neha@company.com | O12: 17443 | P12: =IF(O12<20000,"Below 20K", IF(O12<=40000,"20K-40K", IF(O12<=60000,"40K-60K", IF(O12<=80000,"60K-80K", "Above 80K")))) -> Below 20K | Q12: =COUNTIF($P:$P,"60K-80K") -> 69 | R12: M12 | S12: =TRIM(CLEAN(SUBSTITUTE(R12," ",""))) -> M12 | T12: resigned | U12: =TRIM(UPPER(T12)) -> RESIGNED | V12: =DATEDIF(H12,J12,"D") -> 187 | W12: =DATEDIF(H12,J12,"M") -> 6 | X12: =DATEDIF(H12,J12,"Y") -> 0 | AA12: =IF(AND(O12>80000,X12<2),"CHECK","OK") -> OK
A13: emp12 | B13: =TRIM(UPPER(A13)) -> EMP12 | C13: Pooja | D13: =PROPER(TRIM(C13)) -> Pooja | E13: hr | F13: =TRIM(UPPER(E13)) -> HR | G13: 08-03-2019 | H13: =DATEVALUE(G13) -> 43532 | I13: 2021/05/26 | J13: =IF(I13="",TODAY(),DATEVALUE(I13)) -> 44342 | K13: 9887171748 | L13: =VALUE(K13) -> 9887171748 | M13: SURESH@company.com | N13: =TRIM(LOWER(M13)) -> suresh@company.com | O13: 57006 | P13: =IF(O13<20000,"Below 20K", IF(O13<=40000,"20K-40K", IF(O13<=60000,"40K-60K", IF(O13<=80000,"60K-80K", "Above 80K")))) -> 40K-60K | R13: M20 | S13: =TRIM(CLEAN(SUBSTITUTE(R13," ",""))) -> M20 | T13: Active | U13: =TRIM(UPPER(T13)) -> ACTIVE | V13: =DATEDIF(H13,J13,"D") -> 810 | W13: =DATEDIF(H13,J13,"M") -> 26 | X13: =DATEDIF(H13,J13,"Y") -> 2 | AA13: =IF(AND(O13>80000,X13<2),"CHECK","OK") -> OK
A14: EMP13 | B14: =TRIM(UPPER(A14)) -> EMP13 | C14: SURESH | D14: =PROPER(TRIM(C14)) -> Suresh | E14: HR | F14: =TRIM(UPPER(E14)) -> HR | G14: 2022/09/07 | H14: =DATEVALUE(G14) -> 44811 | I14: 2023/02/07 | J14: =IF(I14="",TODAY(),DATEVALUE(I14)) -> 44964 | K14: 9561915728 | L14: =VALUE(K14) -> 9561915728 | M14: ankit@company.com | N14: =TRIM(LOWER(M14)) -> ankit@company.com | O14: 94507 | P14: =IF(O14<20000,"Below 20K", IF(O14<=40000,"20K-40K", IF(O14<=60000,"40K-60K", IF(O14<=80000,"60K-80K", "Above 80K")))) -> Above 80K | Q14: Above 80K | R14: M24 | S14: =TRIM(CLEAN(SUBSTITUTE(R14," ",""))) -> M24 | T14: On Hold | U14: =TRIM(UPPER(T14)) -> ON HOLD | V14: =DATEDIF(H14,J14,"D") -> 153 | W14: =DATEDIF(H14,J14,"M") -> 5 | X14: =DATEDIF(H14,J14,"Y") -> 0 | AA14: =IF(AND(O14>80000,X14<2),"CHECK","OK") -> CHECK
A15: EMP14 | B15: =TRIM(UPPER(A15)) -> EMP14 | C15: Pooja | D15: =PROPER(TRIM(C15)) -> Pooja | E15: Sales | F15: =TRIM(UPPER(E15)) -> SALES | G15: 2020/06/09 | H15: =DATEVALUE(G15) -> 43991 | J15: =IF(I15="",TODAY(),DATEVALUE(I15)) -> 46024 | K15: 9803274000 | L15: =VALUE(K15) -> 9803274000 | M15: KIRAN@company.com | N15: =TRIM(LOWER(M15)) -> kiran@company.com | O15: 49081 | P15: =IF(O15<20000,"Below 20K", IF(O15<=40000,"20K-40K", IF(O15<=60000,"40K-60K", IF(O15<=80000,"60K-80K", "Above 80K")))) -> 40K-60K | Q15: =COUNTIF($P:$P,"Above 80k") -> 51 | R15: M16 | S15: =TRIM(CLEAN(SUBSTITUTE(R15," ",""))) -> M16 | T15: resigned | U15: =TRIM(UPPER(T15)) -> RESIGNED | V15: =DATEDIF(H15,J15,"D") -> 2033 | W15: =DATEDIF(H15,J15,"M") -> 66 | X15: =DATEDIF(H15,J15,"Y") -> 5 | AA15: =IF(AND(O15>80000,X15<2),"CHECK","OK") -> OK
A16: EMP15 | B16: =TRIM(UPPER(A16)) -> EMP15 | C16: SURESH | D16: =PROPER(TRIM(C16)) -> Suresh | E16: it | F16: =TRIM(UPPER(E16)) -> IT | G16: 08-02-2023 | H16: =DATEVALUE(G16) -> 44965 | I16: 12-07-2025 | J16: =IF(I16="",TODAY(),DATEVALUE(I16)) -> 45850 | K16: 9531992521 | L16: =VALUE(K16) -> 9531992521 | M16: SURESH@company.com | N16: =TRIM(LOWER(M16)) -> suresh@company.com | O16: 69406 | P16: =IF(O16<20000,"Below 20K", IF(O16<=40000,"20K-40K", IF(O16<=60000,"40K-60K", IF(O16<=80000,"60K-80K", "Above 80K")))) -> 60K-80K | R16: M2 | S16: =TRIM(CLEAN(SUBSTITUTE(R16," ",""))) -> M2 | T16: On Hold | U16: =TRIM(UPPER(T16)) -> ON HOLD | V16: =DATEDIF(H16,J16,"D") -> 885 | W16: =DATEDIF(H16,J16,"M") -> 29 | X16: =DATEDIF(H16,J16,"Y") -> 2 | AA16: =IF(AND(O16>80000,X16<2),"CHECK","OK") -> OK
A17: emp16 | B17: =TRIM(UPPER(A17)) -> EMP16 | C17: ankit | D17: =PROPER(TRIM(C17)) -> Ankit | E17: it | F17: =TRIM(UPPER(E17)) -> IT | G17: 2023/11/05 | H17: =DATEVALUE(G17) -> 45235 | I17: 2024/07/14 | J17: =IF(I17="",TODAY(),DATEVALUE(I17)) -> 45487 | K17: 9705437429 | L17: =VALUE(K17) -> 9705437429 | M17: SURESH@gmail.com | N17: =TRIM(LOWER(M17)) -> suresh@gmail.com | O17: 18834 | P17: =IF(O17<20000,"Below 20K", IF(O17<=40000,"20K-40K", IF(O17<=60000,"40K-60K", IF(O17<=80000,"60K-80K", "Above 80K")))) -> Below 20K | R17: M20 | S17: =TRIM(CLEAN(SUBSTITUTE(R17," ",""))) -> M20 | T17: On Hold | U17: =TRIM(UPPER(T17)) -> ON HOLD | V17: =DATEDIF(H17,J17,"D") -> 252 | W17: =DATEDIF(H17,J17,"M") -> 8 | X17: =DATEDIF(H17,J17,"Y") -> 0 | AA17: =IF(AND(O17>80000,X17<2),"CHECK","OK") -> OK
A18: EMP17 | B18: =TRIM(UPPER(A18)) -> EMP17 | C18: neha | D18: =PROPER(TRIM(C18)) -> Neha | E18: IT | F18: =TRIM(UPPER(E18)) -> IT | G18: 2019/05/28 | H18: =DATEVALUE(G18) -> 43613 | I18: 2022/06/25 | J18: =IF(I18="",TODAY(),DATEVALUE(I18)) -> 44737 | K18: 9970816343 | L18: =VALUE(K18) -> 9970816343 | M18: SURESH@company.com | N18: =TRIM(LOWER(M18)) -> suresh@company.com | O18: 38952 | P18: =IF(O18<20000,"Below 20K", IF(O18<=40000,"20K-40K", IF(O18<=60000,"40K-60K", IF(O18<=80000,"60K-80K", "Above 80K")))) -> 20K-40K | R18: M3 | S18: =TRIM(CLEAN(SUBSTITUTE(R18," ",""))) -> M3 | T18: resigned | U18: =TRIM(UPPER(T18)) -> RESIGNED | V18: =DATEDIF(H18,J18,"D") -> 1124 | W18: =DATEDIF(H18,J18,"M") -> 36 | X18: =DATEDIF(H18,J18,"Y") -> 3 | AA18: =IF(AND(O18>80000,X18<2),"CHECK","OK") -> OK
A19: EMP18 | B19: =TRIM(UPPER(A19)) -> EMP18 | C19: ankit | D19: =PROPER(TRIM(C19)) -> Ankit | E19: it | F19: =TRIM(UPPER(E19)) -> IT | G19: 27-03-2020 | H19: =DATEVALUE(G19) -> 43917 | I19: 2020/09/12 | J19: =IF(I19="",TODAY(),DATEVALUE(I19)) -> 44086 | K19: 9131591320 | L19: =VALUE(K19) -> 9131591320 | M19: neha@company.com | N19: =TRIM(LOWER(M19)) -> neha@company.com | O19: 35910 | P19: =IF(O19<20000,"Below 20K", IF(O19<=40000,"20K-40K", IF(O19<=60000,"40K-60K", IF(O19<=80000,"60K-80K", "Above 80K")))) -> 20K-40K | R19: M 20 | S19: =TRIM(CLEAN(SUBSTITUTE(R19," ",""))) -> M20 | T19: resigned | U19: =TRIM(UPPER(T19)) -> RESIGNED | V19: =DATEDIF(H19,J19,"D") -> 169 | W19: =DATEDIF(H19,J19,"M") -> 5 | X19: =DATEDIF(H19,J19,"Y") -> 0 | AA19: =IF(AND(O19>80000,X19<2),"CHECK","OK") -> OK
A20: EMP19 | B20: =TRIM(UPPER(A20)) -> EMP19 | C20: vikas | D20: =PROPER(TRIM(C20)) -> Vikas | E20: hr | F20: =TRIM(UPPER(E20)) -> HR | G20: 2020/01/21 | H20: =DATEVALUE(G20) -> 43851 | I20: 2022/11/09 | J20: =IF(I20="",TODAY(),DATEVALUE(I20)) -> 44874 | K20: 9544962090 | L20: =VALUE(K20) -> 9544962090 | M20: vikas@company.com | N20: =TRIM(LOWER(M20)) -> vikas@company.com | O20: 30231 | P20: =IF(O20<20000,"Below 20K", IF(O20<=40000,"20K-40K", IF(O20<=60000,"40K-60K", IF(O20<=80000,"60K-80K", "Above 80K")))) -> 20K-40K | R20: M10 | S20: =TRIM(CLEAN(SUBSTITUTE(R20," ",""))) -> M10 | T20: resigned | U20: =TRIM(UPPER(T20)) -> RESIGNED | V20: =DATEDIF(H20,J20,"D") -> 1023 | W20: =DATEDIF(H20,J20,"M") -> 33 | X20: =DATEDIF(H20,J20,"Y") -> 2 | AA20: =IF(AND(O20>80000,X20<2),"CHECK","OK") -> OK
A21: emp20 | B21: =TRIM(UPPER(A21)) -> EMP20 | C21: vikas | D21: =PROPER(TRIM(C21)) -> Vikas | E21: it | F21: =TRIM(UPPER(E21)) -> IT | G21: 2023/08/23 | H21: =DATEVALUE(G21) -> 45161 | I21: 23-01-2025 | J21: =IF(I21="",TODAY(),DATEVALUE(I21)) -> 45680 | K21: 9274871734 | L21: =VALUE(K21) -> 9274871734 | M21: SURESH@company.com | N21: =TRIM(LOWER(M21)) -> suresh@company.com | O21: 75026 | P21: =IF(O21<20000,"Below 20K", IF(O21<=40000,"20K-40K", IF(O21<=60000,"40K-60K", IF(O21<=80000,"60K-80K", "Above 80K")))) -> 60K-80K | R21: M3 | S21: =TRIM(CLEAN(SUBSTITUTE(R21," ",""))) -> M3 | T21: RESIGNED | U21: =TRIM(UPPER(T21)) -> RESIGNED | V21: =DATEDIF(H21,J21,"D") -> 519 | W21: =DATEDIF(H21,J21,"M") -> 17 | X21: =DATEDIF(H21,J21,"Y") -> 1 | AA21: =IF(AND(O21>80000,X21<2),"CHECK","OK") -> OK
A22: EMP21 | B22: =TRIM(UPPER(A22)) -> EMP21 | C22: neha | D22: =PROPER(TRIM(C22)) -> Neha | E22: hr | F22: =TRIM(UPPER(E22)) -> HR | G22: 21-07-2022 | H22: =DATEVALUE(G22) -> 44763 | J22: =IF(I22="",TODAY(),DATEVALUE(I22)) -> 46024 | K22: 9260910861 | L22: =VALUE(K22) -> 9260910861 | M22: ravi@company.com | N22: =TRIM(LOWER(M22)) -> ravi@company.com | O22: 56487 | P22: =IF(O22<20000,"Below 20K", IF(O22<=40000,"20K-40K", IF(O22<=60000,"40K-60K", IF(O22<=80000,"60K-80K", "Above 80K")))) -> 40K-60K | R22: M9 | S22: =TRIM(CLEAN(SUBSTITUTE(R22," ",""))) -> M9 | T22: On Hold | U22: =TRIM(UPPER(T22)) -> ON HOLD | V22: =DATEDIF(H22,J22,"D") -> 1261 | W22: =DATEDIF(H22,J22,"M") -> 41 | X22: =DATEDIF(H22,J22,"Y") -> 3 | AA22: =IF(AND(O22>80000,X22<2),"CHECK","OK") -> OK
A23: EMP22 | B23: =TRIM(UPPER(A23)) -> EMP22 | C23: RAHUL | D23: =PROPER(TRIM(C23)) -> Rahul | E23: HR | F23: =TRIM(UPPER(E23)) -> HR | G23: 2022/05/04 | H23: =DATEVALUE(G23) -> 44685 | I23: 2024/03/26 | J23: =IF(I23="",TODAY(),DATEVALUE(I23)) -> 45377 | K23: 9864320135 | L23: =VALUE(K23) -> 9864320135 | M23: RAHUL@company.com | N23: =TRIM(LOWER(M23)) -> rahul@company.com | O23: 13552 | P23: =IF(O23<20000,"Below 20K", IF(O23<=40000,"20K-40K", IF(O23<=60000,"40K-60K", IF(O23<=80000,"60K-80K", "Above 80K")))) -> Below 20K | R23: M13 | S23: =TRIM(CLEAN(SUBSTITUTE(R23," ",""))) -> M13 | T23: RESIGNED | U23: =TRIM(UPPER(T23)) -> RESIGNED | V23: =DATEDIF(H23,J23,"D") -> 692 | W23: =DATEDIF(H23,J23,"M") -> 22 | X23: =DATEDIF(H23,J23,"Y") -> 1 | AA23: =IF(AND(O23>80000,X23<2),"CHECK","OK") -> OK
A24: EMP23 | B24: =TRIM(UPPER(A24)) -> EMP23 | C24: vikas | D24: =PROPER(TRIM(C24)) -> Vikas | E24: it | F24: =TRIM(UPPER(E24)) -> IT | G24: 2022/12/23 | H24: =DATEVALUE(G24) -> 44918 | I24: 2024/04/27 | J24: =IF(I24="",TODAY(),DATEVALUE(I24)) -> 45409 | K24: 9967616524 | L24: =VALUE(K24) -> 9967616524 | M24: KIRAN@company.com | N24: =TRIM(LOWER(M24)) -> kiran@company.com | O24: 20431 | P24: =IF(O24<20000,"Below 20K", IF(O24<=40000,"20K-40K", IF(O24<=60000,"40K-60K", IF(O24<=80000,"60K-80K", "Above 80K")))) -> 20K-40K | R24: M5 | S24: =TRIM(CLEAN(SUBSTITUTE(R24," ",""))) -> M5 | T24: On Hold | U24: =TRIM(UPPER(T24)) -> ON HOLD | V24: =DATEDIF(H24,J24,"D") -> 491 | W24: =DATEDIF(H24,J24,"M") -> 16 | X24: =DATEDIF(H24,J24,"Y") -> 1 | AA24: =IF(AND(O24>80000,X24<2),"CHECK","OK") -> OK
A25: emp24 | B25: =TRIM(UPPER(A25)) -> EMP24 | C25: Pooja | D25: =PROPER(TRIM(C25)) -> Pooja | E25: HR | F25: =TRIM(UPPER(E25)) -> HR | G25: 31-05-2021 | H25: =DATEVALUE(G25) -> 44347 | I25: 2025/03/25 | J25: =IF(I25="",TODAY(),DATEVALUE(I25)) -> 45741 | K25: 9540236491 | L25: =VALUE(K25) -> 9540236491 | M25: neha@gmail.com | N25: =TRIM(LOWER(M25)) -> neha@gmail.com | O25: 89209 | P25: =IF(O25<20000,"Below 20K", IF(O25<=40000,"20K-40K", IF(O25<=60000,"40K-60K", IF(O25<=80000,"60K-80K", "Above 80K")))) -> Above 80K | R25: M19 | S25: =TRIM(CLEAN(SUBSTITUTE(R25," ",""))) -> M19 | T25: Active | U25: =TRIM(UPPER(T25)) -> ACTIVE | V25: =DATEDIF(H25,J25,"D") -> 1394 | W25: =DATEDIF(H25,J25,"M") -> 45 | X25: =DATEDIF(H25,J25,"Y") -> 3 | AA25: =IF(AND(O25>80000,X25<2),"CHECK","OK") -> OK
A26: EMP25 | B26: =TRIM(UPPER(A26)) -> EMP25 | C26: Sunita | D26: =PROPER(TRIM(C26)) -> Sunita | E26: sales | F26: =TRIM(UPPER(E26)) -> SALES | G26: 2019/11/12 | H26: =DATEVALUE(G26) -> 43781 | I26: 23-06-2021 | J26: =IF(I26="",TODAY(),DATEVALUE(I26)) -> 44370 | K26: 9335638101 | L26: =VALUE(K26) -> 9335638101 | M26: neha@company.com | N26: =TRIM(LOWER(M26)) -> neha@company.com | O26: 26420 | P26: =IF(O26<20000,"Below 20K", IF(O26<=40000,"20K-40K", IF(O26<=60000,"40K-60K", IF(O26<=80000,"60K-80K", "Above 80K")))) -> 20K-40K | R26: M20 | S26: =TRIM(CLEAN(SUBSTITUTE(R26," ",""))) -> M20 | T26: resigned | U26: =TRIM(UPPER(T26)) -> RESIGNED | V26: =DATEDIF(H26,J26,"D") -> 589 | W26: =DATEDIF(H26,J26,"M") -> 19 | X26: =DATEDIF(H26,J26,"Y") -> 1 | AA26: =IF(AND(O26>80000,X26<2),"CHECK","OK") -> OK
A27: EMP26 | B27: =TRIM(UPPER(A27)) -> EMP26 | C27: Sunita | D27: =PROPER(TRIM(C27)) -> Sunita | E27: sales | F27: =TRIM(UPPER(E27)) -> SALES | G27: 2019/04/07 | H27: =DATEVALUE(G27) -> 43562 | I27: 2021/07/15 | J27: =IF(I27="",TODAY(),DATEVALUE(I27)) -> 44392 | K27: 9567209295 | L27: =VALUE(K27) -> 9567209295 | M27: RAHUL@company.com | N27: =TRIM(LOWER(M27)) -> rahul@company.com | O27: 48833 | P27: =IF(O27<20000,"Below 20K", IF(O27<=40000,"20K-40K", IF(O27<=60000,"40K-60K", IF(O27<=80000,"60K-80K", "Above 80K")))) -> 40K-60K | R27: M15 | S27: =TRIM(CLEAN(SUBSTITUTE(R27," ",""))) -> M15 | T27: Active | U27: =TRIM(UPPER(T27)) -> ACTIVE | V27: =DATEDIF(H27,J27,"D") -> 830 | W27: =DATEDIF(H27,J27,"M") -> 27 | X27: =DATEDIF(H27,J27,"Y") -> 2 | AA27: =IF(AND(O27>80000,X27<2),"CHECK","OK") -> OK
A28: EMP27 | B28: =TRIM(UPPER(A28)) -> EMP27 | C28: Amit | D28: =PROPER(TRIM(C28)) -> Amit | E28: finance | F28: =TRIM(UPPER(E28)) -> FINANCE | G28: 26-03-2023 | H28: =DATEVALUE(G28) -> 45011 | I28: 2026/11/26 | J28: =IF(I28="",TODAY(),DATEVALUE(I28)) -> 46352 | K28: 9430931644 | L28: =VALUE(K28) -> 9430931644 | M28: SURESH@company.com | N28: =TRIM(LOWER(M28)) -> suresh@company.com | O28: 17678 | P28: =IF(O28<20000,"Below 20K", IF(O28<=40000,"20K-40K", IF(O28<=60000,"40K-60K", IF(O28<=80000,"60K-80K", "Above 80K")))) -> Below 20K | R28: M 25 | S28: =TRIM(CLEAN(SUBSTITUTE(R28," ",""))) -> M25 | T28: On Hold | U28: =TRIM(UPPER(T28)) -> ON HOLD | V28: =DATEDIF(H28,J28,"D") -> 1341 | W28: =DATEDIF(H28,J28,"M") -> 44 | X28: =DATEDIF(H28,J28,"Y") -> 3 | AA28: =IF(AND(O28>80000,X28<2),"CHECK","OK") -> OK
A29: emp28 | B29: =TRIM(UPPER(A29)) -> EMP28 | C29: vikas | D29: =PROPER(TRIM(C29)) -> Vikas | E29: Sales | F29: =TRIM(UPPER(E29)) -> SALES | G29: 2021/05/14 | H29: =DATEVALUE(G29) -> 44330 | J29: =IF(I29="",TODAY(),DATEVALUE(I29)) -> 46024 | K29: 9695781322 | L29: =VALUE(K29) -> 9695781322 | M29: ankit@company.com | N29: =TRIM(LOWER(M29)) -> ankit@company.com | O29: 52795 | P29: =IF(O29<20000,"Below 20K", IF(O29<=40000,"20K-40K", IF(O29<=60000,"40K-60K", IF(O29<=80000,"60K-80K", "Above 80K")))) -> 40K-60K | R29: M23 | S29: =TRIM(CLEAN(SUBSTITUTE(R29," ",""))) -> M23 | T29: Active | U29: =TRIM(UPPER(T29)) -> ACTIVE | V29: =DATEDIF(H29,J29,"D") -> 1694 | W29: =DATEDIF(H29,J29,"M") -> 55 | X29: =DATEDIF(H29,J29,"Y") -> 4 | AA29: =IF(AND(O29>80000,X29<2),"CHECK","OK") -> OK
A30: EMP29 | B30: =TRIM(UPPER(A30)) -> EMP29 | C30: vikas | D30: =PROPER(TRIM(C30)) -> Vikas | E30: finance | F30: =TRIM(UPPER(E30)) -> FINANCE | G30: 2021/06/05 | H30: =DATEVALUE(G30) -> 44352 | I30: 2025/01/01 | J30: =IF(I30="",TODAY(),DATEVALUE(I30)) -> 45658 | K30: 9119025269 | L30: =VALUE(K30) -> 9119025269 | M30: SURESH@company.com | N30: =TRIM(LOWER(M30)) -> suresh@company.com | O30: 16285 | P30: =IF(O30<20000,"Below 20K", IF(O30<=40000,"20K-40K", IF(O30<=60000,"40K-60K", IF(O30<=80000,"60K-80K", "Above 80K")))) -> Below 20K | R30: M19 | S30: =TRIM(CLEAN(SUBSTITUTE(R30," ",""))) -> M19 | T30: On Hold | U30: =TRIM(UPPER(T30)) -> ON HOLD | V30: =DATEDIF(H30,J30,"D") -> 1306 | W30: =DATEDIF(H30,J30,"M") -> 42 | X30: =DATEDIF(H30,J30,"Y") -> 3 | AA30: =IF(AND(O30>80000,X30<2),"CHECK","OK") -> OK
A31: EMP30 | B31: =TRIM(UPPER(A31)) -> EMP30 | C31: RAHUL | D31: =PROPER(TRIM(C31)) -> Rahul | E31: finance | F31: =TRIM(UPPER(E31)) -> FINANCE | G31: 26-01-2019 | H31: =DATEVALUE(G31) -> 43491 | I31: 10-02-2022 | J31: =IF(I31="",TODAY(),DATEVALUE(I31)) -> 44602 | K31: 9903352588 | L31: =VALUE(K31) -> 9903352588 | M31: KIRAN@company.com | N31: =TRIM(LOWER(M31)) -> kiran@company.com | O31: 16098 | P31: =IF(O31<20000,"Below 20K", IF(O31<=40000,"20K-40K", IF(O31<=60000,"40K-60K", IF(O31<=80000,"60K-80K", "Above 80K")))) -> Below 20K | R31: M14 | S31: =TRIM(CLEAN(SUBSTITUTE(R31," ",""))) -> M14 | T31: active | U31: =TRIM(UPPER(T31)) -> ACTIVE | V31: =DATEDIF(H31,J31,"D") -> 1111 | W31: =DATEDIF(H31,J31,"M") -> 36 | X31: =DATEDIF(H31,J31,"Y") -> 3 | AA31: =IF(AND(O31>80000,X31<2),"CHECK","OK") -> OK
A32: EMP31 | B32: =TRIM(UPPER(A32)) -> EMP31 | C32: SURESH | D32: =PROPER(TRIM(C32)) -> Suresh | E32: sales | F32: =TRIM(UPPER(E32)) -> SALES | G32: 2023/09/06 | H32: =DATEVALUE(G32) -> 45175 | I32: 2027/07/07 | J32: =IF(I32="",TODAY(),DATEVALUE(I32)) -> 46575 | K32: 9728495167 | L32: =VALUE(K32) -> 9728495167 | M32: vikas@company.com | N32: =TRIM(LOWER(M32)) -> vikas@company.com | O32: 31220 | P32: =IF(O32<20000,"Below 20K", IF(O32<=40000,"20K-40K", IF(O32<=60000,"40K-60K", IF(O32<=80000,"60K-80K", "Above 80K")))) -> 20K-40K | R32: M14 | S32: =TRIM(CLEAN(SUBSTITUTE(R32," ",""))) -> M14 | T32: RESIGNED | U32: =TRIM(UPPER(T32)) -> RESIGNED | V32: =DATEDIF(H32,J32,"D") -> 1400 | W32: =DATEDIF(H32,J32,"M") -> 46 | X32: =DATEDIF(H32,J32,"Y") -> 3 | AA32: =IF(AND(O32>80000,X32<2),"CHECK","OK") -> OK
A33: emp32 | B33: =TRIM(UPPER(A33)) -> EMP32 | C33: vikas | D33: =PROPER(TRIM(C33)) -> Vikas | E33: sales | F33: =TRIM(UPPER(E33)) -> SALES | G33: 2023/11/02 | H33: =DATEVALUE(G33) -> 45232 | I33: 2026/10/28 | J33: =IF(I33="",TODAY(),DATEVALUE(I33)) -> 46323 | K33: 9693492287 | L33: =VALUE(K33) -> 9693492287 | M33: SURESH@gmail.com | N33: =TRIM(LOWER(M33)) -> suresh@gmail.com | O33: 58293 | P33: =IF(O33<20000,"Below 20K", IF(O33<=40000,"20K-40K", IF(O33<=60000,"40K-60K", IF(O33<=80000,"60K-80K", "Above 80K")))) -> 40K-60K | R33: M6 | S33: =TRIM(CLEAN(SUBSTITUTE(R33," ",""))) -> M6 | T33: Active | U33: =TRIM(UPPER(T33)) -> ACTIVE | V33: =DATEDIF(H33,J33,"D") -> 1091 | W33: =DATEDIF(H33,J33,"M") -> 35 | X33: =DATEDIF(H33,J33,"Y") -> 2 | AA33: =IF(AND(O33>80000,X33<2),"CHECK","OK") -> OK
A34: EMP33 | B34: =TRIM(UPPER(A34)) -> EMP33 | C34: neha | D34: =PROPER(TRIM(C34)) -> Neha | E34: IT | F34: =TRIM(UPPER(E34)) -> IT | G34: 20-11-2020 | H34: =DATEVALUE(G34) -> 44155 | I34: 2022/09/25 | J34: =IF(I34="",TODAY(),DATEVALUE(I34)) -> 44829 | K34: 9314756300 | L34: =VALUE(K34) -> 9314756300 | M34: Sunita@company.com | N34: =TRIM(LOWER(M34)) -> sunita@company.com | O34: 33146 | P34: =IF(O34<20000,"Below 20K", IF(O34<=40000,"20K-40K", IF(O34<=60000,"40K-60K", IF(O34<=80000,"60K-80K", "Above 80K")))) -> 20K-40K | R34: M23 | S34: =TRIM(CLEAN(SUBSTITUTE(R34," ",""))) -> M23 | T34: active | U34: =TRIM(UPPER(T34)) -> ACTIVE | V34: =DATEDIF(H34,J34,"D") -> 674 | W34: =DATEDIF(H34,J34,"M") -> 22 | X34: =DATEDIF(H34,J34,"Y") -> 1 | AA34: =IF(AND(O34>80000,X34<2),"CHECK","OK") -> OK
A35: EMP34 | B35: =TRIM(UPPER(A35)) -> EMP34 | C35: KIRAN | D35: =PROPER(TRIM(C35)) -> Kiran | E35: IT | F35: =TRIM(UPPER(E35)) -> IT | G35: 2023/04/23 | H35: =DATEVALUE(G35) -> 45039 | I35: 2025/09/06 | J35: =IF(I35="",TODAY(),DATEVALUE(I35)) -> 45906 | K35: 9590240821 | L35: =VALUE(K35) -> 9590240821 | M35: Amit@company.com | N35: =TRIM(LOWER(M35)) -> amit@company.com | O35: 59375 | P35: =IF(O35<20000,"Below 20K", IF(O35<=40000,"20K-40K", IF(O35<=60000,"40K-60K", IF(O35<=80000,"60K-80K", "Above 80K")))) -> 40K-60K | R35: M12 | S35: =TRIM(CLEAN(SUBSTITUTE(R35," ",""))) -> M12 | T35: Active | U35: =TRIM(UPPER(T35)) -> ACTIVE | V35: =DATEDIF(H35,J35,"D") -> 867 | W35: =DATEDIF(H35,J35,"M") -> 28 | X35: =DATEDIF(H35,J35,"Y") -> 2 | AA35: =IF(AND(O35>80000,X35<2),"CHECK","OK") -> OK
A36: EMP35 | B36: =TRIM(UPPER(A36)) -> EMP35 | C36: Pooja | D36: =PROPER(TRIM(C36)) -> Pooja | E36: sales | F36: =TRIM(UPPER(E36)) -> SALES | G36: 2023/04/03 | H36: =DATEVALUE(G36) -> 45019 | J36: =IF(I36="",TODAY(),DATEVALUE(I36)) -> 46024 | K36: 9113594175 | L36: =VALUE(K36) -> 9113594175 | M36: RAHUL@company.com | N36: =TRIM(LOWER(M36)) -> rahul@company.com | O36: 89758 | P36: =IF(O36<20000,"Below 20K", IF(O36<=40000,"20K-40K", IF(O36<=60000,"40K-60K", IF(O36<=80000,"60K-80K", "Above 80K")))) -> Above 80K | R36: M7 | S36: =TRIM(CLEAN(SUBSTITUTE(R36," ",""))) -> M7 | T36: On Hold | U36: =TRIM(UPPER(T36)) -> ON HOLD | V36: =DATEDIF(H36,J36,"D") -> 1005 | W36: =DATEDIF(H36,J36,"M") -> 32 | X36: =DATEDIF(H36,J36,"Y") -> 2 | AA36: =IF(AND(O36>80000,X36<2),"CHECK","OK") -> OK
A37: emp36 | B37: =TRIM(UPPER(A37)) -> EMP36 | C37: RAHUL | D37: =PROPER(TRIM(C37)) -> Rahul | E37: Finance | F37: =TRIM(UPPER(E37)) -> FINANCE | G37: 09-12-2020 | H37: =DATEVALUE(G37) -> 44174 | I37: 2023/05/07 | J37: =IF(I37="",TODAY(),DATEVALUE(I37)) -> 45053 | K37: 9272201115 | L37: =VALUE(K37) -> 9272201115 | M37: ravi@company.com | N37: =TRIM(LOWER(M37)) -> ravi@company.com | O37: 26049 | P37: =IF(O37<20000,"Below 20K", IF(O37<=40000,"20K-40K", IF(O37<=60000,"40K-60K", IF(O37<=80000,"60K-80K", "Above 80K")))) -> 20K-40K | R37: M 16 | S37: =TRIM(CLEAN(SUBSTITUTE(R37," ",""))) -> M16 | T37: resigned | U37: =TRIM(UPPER(T37)) -> RESIGNED | V37: =DATEDIF(H37,J37,"D") -> 879 | W37: =DATEDIF(H37,J37,"M") -> 28 | X37: =DATEDIF(H37,J37,"Y") -> 2 | AA37: =IF(AND(O37>80000,X37<2),"CHECK","OK") -> OK
A38: EMP37 | B38: =TRIM(UPPER(A38)) -> EMP37 | C38: ankit | D38: =PROPER(TRIM(C38)) -> Ankit | E38: HR | F38: =TRIM(UPPER(E38)) -> HR | G38: 2019/07/06 | H38: =DATEVALUE(G38) -> 43652 | I38: 2021/03/21 | J38: =IF(I38="",TODAY(),DATEVALUE(I38)) -> 44276 | K38: 9390036297 | L38: =VALUE(K38) -> 9390036297 | M38: Amit@company.com | N38: =TRIM(LOWER(M38)) -> amit@company.com | O38: 44609 | P38: =IF(O38<20000,"Below 20K", IF(O38<=40000,"20K-40K", IF(O38<=60000,"40K-60K", IF(O38<=80000,"60K-80K", "Above 80K")))) -> 40K-60K | R38: M2 | S38: =TRIM(CLEAN(SUBSTITUTE(R38," ",""))) -> M2 | T38: On Hold | U38: =TRIM(UPPER(T38)) -> ON HOLD | V38: =DATEDIF(H38,J38,"D") -> 624 | W38: =DATEDIF(H38,J38,"M") -> 20 | X38: =DATEDIF(H38,J38,"Y") -> 1 | AA38: =IF(AND(O38>80000,X38<2),"CHECK","OK") -> OK
A39: EMP38 | B39: =TRIM(UPPER(A39)) -> EMP38 | C39: KIRAN | D39: =PROPER(TRIM(C39)) -> Kiran | E39: hr | F39: =TRIM(UPPER(E39)) -> HR | G39: 2021/02/07 | H39: =DATEVALUE(G39) -> 44234 | I39: 2021/07/26 | J39: =IF(I39="",TODAY(),DATEVALUE(I39)) -> 44403 | K39: 9608496639 | L39: =VALUE(K39) -> 9608496639 | M39: vikas@company.com | N39: =TRIM(LOWER(M39)) -> vikas@company.com | O39: 38415 | P39: =IF(O39<20000,"Below 20K", IF(O39<=40000,"20K-40K", IF(O39<=60000,"40K-60K", IF(O39<=80000,"60K-80K", "Above 80K")))) -> 20K-40K | R39: M23 | S39: =TRIM(CLEAN(SUBSTITUTE(R39," ",""))) -> M23 | T39: active | U39: =TRIM(UPPER(T39)) -> ACTIVE | V39: =DATEDIF(H39,J39,"D") -> 169 | W39: =DATEDIF(H39,J39,"M") -> 5 | X39: =DATEDIF(H39,J39,"Y") -> 0 | AA39: =IF(AND(O39>80000,X39<2),"CHECK","OK") -> OK
A40: EMP39 | B40: =TRIM(UPPER(A40)) -> EMP39 | C40: ankit | D40: =PROPER(TRIM(C40)) -> Ankit | E40: hr | F40: =TRIM(UPPER(E40)) -> HR | G40: 15-06-2020 | H40: =DATEVALUE(G40) -> 43997 | I40: 2022/07/07 | J40: =IF(I40="",TODAY(),DATEVALUE(I40)) -> 44749 | K40: 9944362729 | L40: =VALUE(K40) -> 9944362729 | M40: RAHUL@company.com | N40: =TRIM(LOWER(M40)) -> rahul@company.com | O40: 53603 | P40: =IF(O40<20000,"Below 20K", IF(O40<=40000,"20K-40K", IF(O40<=60000,"40K-60K", IF(O40<=80000,"60K-80K", "Above 80K")))) -> 40K-60K | R40: M12 | S40: =TRIM(CLEAN(SUBSTITUTE(R40," ",""))) -> M12 | T40: On Hold | U40: =TRIM(UPPER(T40)) -> ON HOLD | V40: =DATEDIF(H40,J40,"D") -> 752 | W40: =DATEDIF(H40,J40,"M") -> 24 | X40: =DATEDIF(H40,J40,"Y") -> 2 | AA40: =IF(AND(O40>80000,X40<2),"CHECK","OK") -> OK
...

Sheet Clean_Data
A1: Emp ID Clean | B1: Emp Name Clean | C1: Department Clean | D1: Join Date Clean | E1: End Date Clean | F1: Mobile No Clean | G1: Email Clean | H1: Salary | I1: Salary Range | J1: Salary Range Count Below 20K | K1: Salary Range Count 20K-40k | L1: Salary Range Count 40k-60k | M1: Salary Range Count 60k-80k | N1: Salary Range Count Above 80k | O1: Manager ID Clean | P1: Status Clean | Q1: Experience Days | R1: Experience Months | S1: Experience Years | T1: Total Resigned | U1: Total Active | V1: Total On Hold | W1: Avg Exp Resi Emp Years | X1: Avg Exp Active Emp Months | Y1: Highest 1st Salary | Z1: Highest 5th Salary | AA1: High Salary & Low Exp Audit
A2: =Messy_Data!B2 -> EMP1 | B2: =Messy_Data!D2 -> Ravi | C2: =Messy_Data!F2 -> IT | D2: =Messy_Data!H2 -> 44578 | E2: =Messy_Data!J2 -> 45720 | F2: =Messy_Data!L2 -> 9878481087 | G2: =Messy_Data!N2 -> amit@company.com | H2: =Messy_Data!O2 -> 16661 | I2: =Messy_Data!P2 -> Below 20K | J2: =Messy_Data!Q3 -> 38 | K2: =Messy_Data!Q6 -> 76 | L2: =Messy_Data!Q9 -> 66 | M2: =Messy_Data!Q12 -> 69 | N2: =Messy_Data!Q15 -> 51 | O2: =Messy_Data!S2 -> M4 | P2: =Messy_Data!U2 -> RESIGNED | Q2: =Messy_Data!V2 -> 1142 | R2: =Messy_Data!W2 -> 37 | S2: =Messy_Data!X2 -> 3 | T2: =Messy_Data!Y2 -> 120 | U2: =Messy_Data!Y5 -> 105 | V2: =Messy_Data!Y8 -> 75 | W2: =Messy_Data!Z2 -> 1.9166667 | X2: =Messy_Data!Z5 -> 29.066667 | Y2: =Messy_Data!Z8 -> 94569 | Z2: =Messy_Data!Z11 -> 94195 | AA2: =Messy_Data!AA2 -> OK
A3: =Messy_Data!B3 -> EMP2 | B3: =Messy_Data!D3 -> Ravi | C3: =Messy_Data!F3 -> FINANCE | D3: =Messy_Data!H3 -> 45151 | E3: =Messy_Data!J3 -> 45245 | F3: =Messy_Data!L3 -> 9377218497 | G3: =Messy_Data!N3 -> pooja@company.com | H3: =Messy_Data!O3 -> 66881 | I3: =Messy_Data!P3 -> 60K-80K | O3: =Messy_Data!S3 -> M8 | P3: =Messy_Data!U3 -> RESIGNED | Q3: =Messy_Data!V3 -> 94 | R3: =Messy_Data!W3 -> 3 | S3: =Messy_Data!X3 -> 0 | AA3: =Messy_Data!AA3 -> OK
A4: =Messy_Data!B4 -> EMP3 | B4: =Messy_Data!D4 -> Ankit | C4: =Messy_Data!F4 -> HR | D4: =Messy_Data!H4 -> 44890 | E4: =Messy_Data!J4 -> 44997 | F4: =Messy_Data!L4 -> 9595920356 | G4: =Messy_Data!N4 -> suresh@company.com | H4: =Messy_Data!O4 -> 86913 | I4: =Messy_Data!P4 -> Above 80K | O4: =Messy_Data!S4 -> M3 | P4: =Messy_Data!U4 -> ON HOLD | Q4: =Messy_Data!V4 -> 107 | R4: =Messy_Data!W4 -> 3 | S4: =Messy_Data!X4 -> 0 | AA4: =Messy_Data!AA4 -> CHECK
A5: =Messy_Data!B5 -> EMP4 | B5: =Messy_Data!D5 -> Ravi | C5: =Messy_Data!F5 -> IT | D5: =Messy_Data!H5 -> 44088 | E5: =Messy_Data!J5 -> 44598 | F5: =Messy_Data!L5 -> 9941224943 | G5: =Messy_Data!N5 -> neha@company.com | H5: =Messy_Data!O5 -> 33885 | I5: =Messy_Data!P5 -> 20K-40K | O5: =Messy_Data!S5 -> M8 | P5: =Messy_Data!U5 -> ACTIVE | Q5: =Messy_Data!V5 -> 510 | R5: =Messy_Data!W5 -> 16 | S5: =Messy_Data!X5 -> 1 | AA5: =Messy_Data!AA5 -> OK
A6: =Messy_Data!B6 -> EMP5 | B6: =Messy_Data!D6 -> Amit | C6: =Messy_Data!F6 -> SALES | D6: =Messy_Data!H6 -> 44516 | E6: =Messy_Data!J6 -> 45889 | F6: =Messy_Data!L6 -> 9245370465 | G6: =Messy_Data!N6 -> ravi@company.com | H6: =Messy_Data!O6 -> 94504 | I6: =Messy_Data!P6 -> Above 80K | O6: =Messy_Data!S6 -> M9 | P6: =Messy_Data!U6 -> RESIGNED | Q6: =Messy_Data!V6 -> 1373 | R6: =Messy_Data!W6 -> 45 | S6: =Messy_Data!X6 -> 3 | AA6: =Messy_Data!AA6 -> OK
A7: =Messy_Data!B7 -> EMP6 | B7: =Messy_Data!D7 -> Sunita | C7: =Messy_Data!F7 -> FINANCE | D7: =Messy_Data!H7 -> 43744 | E7: =Messy_Data!J7 -> 43898 | F7: =Messy_Data!L7 -> 9349938125 | G7: =Messy_Data!N7 -> kiran@company.com | H7: =Messy_Data!O7 -> 49791 | I7: =Messy_Data!P7 -> 40K-60K | O7: =Messy_Data!S7 -> M16 | P7: =Messy_Data!U7 -> RESIGNED | Q7: =Messy_Data!V7 -> 154 | R7: =Messy_Data!W7 -> 5 | S7: =Messy_Data!X7 -> 0 | AA7: =Messy_Data!AA7 -> OK
A8: =Messy_Data!B8 -> EMP7 | B8: =Messy_Data!D8 -> Ravi | C8: =Messy_Data!F8 -> FINANCE | D8: =Messy_Data!H8 -> 44214 | E8: =Messy_Data!J8 -> 46024 | F8: =Messy_Data!L8 -> 9900001110 | G8: =Messy_Data!N8 -> kiran@company.com | H8: =Messy_Data!O8 -> 86686 | I8: =Messy_Data!P8 -> Above 80K | O8: =Messy_Data!S8 -> M2 | P8: =Messy_Data!U8 -> RESIGNED | Q8: =Messy_Data!V8 -> 1810 | R8: =Messy_Data!W8 -> 59 | S8: =Messy_Data!X8 -> 4 | AA8: =Messy_Data!AA8 -> OK
A9: =Messy_Data!B9 -> EMP8 | B9: =Messy_Data!D9 -> Sunita | C9: =Messy_Data!F9 -> HR | D9: =Messy_Data!H9 -> 44726 | E9: =Messy_Data!J9 -> 46061 | F9: =Messy_Data!L9 -> 9125742616 | G9: =Messy_Data!N9 -> pooja@gmail.com | H9: =Messy_Data!O9 -> 37975 | I9: =Messy_Data!P9 -> 20K-40K | O9: =Messy_Data!S9 -> M13 | P9: =Messy_Data!U9 -> ACTIVE | Q9: =Messy_Data!V9 -> 1335 | R9: =Messy_Data!W9 -> 43 | S9: =Messy_Data!X9 -> 3 | AA9: =Messy_Data!AA9 -> OK
A10: =Messy_Data!B10 -> EMP9 | B10: =Messy_Data!D10 -> Pooja | C10: =Messy_Data!F10 -> IT | D10: =Messy_Data!H10 -> 44959 | E10: =Messy_Data!J10 -> 45844 | F10: =Messy_Data!L10 -> 9188103283 | G10: =Messy_Data!N10 -> neha@company.com | H10: =Messy_Data!O10 -> 18480 | I10: =Messy_Data!P10 -> Below 20K | O10: =Messy_Data!S10 -> M13 | P10: =Messy_Data!U10 -> RESIGNED | Q10: =Messy_Data!V10 -> 885 | R10: =Messy_Data!W10 -> 29 | S10: =Messy_Data!X10 -> 2 | AA10: =Messy_Data!AA10 -> OK
A11: =Messy_Data!B11 -> EMP10 | B11: =Messy_Data!D11 -> Ravi | C11: =Messy_Data!F11 -> IT | D11: =Messy_Data!H11 -> 44424 | E11: =Messy_Data!J11 -> 45026 | F11: =Messy_Data!L11 -> 9526289266 | G11: =Messy_Data!N11 -> sunita@company.com | H11: =Messy_Data!O11 -> 72669 | I11: =Messy_Data!P11 -> 60K-80K | O11: =Messy_Data!S11 -> M14 | P11: =Messy_Data!U11 -> ON HOLD | Q11: =Messy_Data!V11 -> 602 | R11: =Messy_Data!W11 -> 19 | S11: =Messy_Data!X11 -> 1 | AA11: =Messy_Data!AA11 -> OK
A12: =Messy_Data!B12 -> EMP11 | B12: =Messy_Data!D12 -> Sunita | C12: =Messy_Data!F12 -> HR | D12: =Messy_Data!H12 -> 43497 | E12: =Messy_Data!J12 -> 43684 | F12: =Messy_Data!L12 -> 9302136537 | G12: =Messy_Data!N12 -> neha@company.com | H12: =Messy_Data!O12 -> 17443 | I12: =Messy_Data!P12 -> Below 20K | O12: =Messy_Data!S12 -> M12 | P12: =Messy_Data!U12 -> RESIGNED | Q12: =Messy_Data!V12 -> 187 | R12: =Messy_Data!W12 -> 6 | S12: =Messy_Data!X12 -> 0 | AA12: =Messy_Data!AA12 -> OK
A13: =Messy_Data!B13 -> EMP12 | B13: =Messy_Data!D13 -> Pooja | C13: =Messy_Data!F13 -> HR | D13: =Messy_Data!H13 -> 43532 | E13: =Messy_Data!J13 -> 44342 | F13: =Messy_Data!L13 -> 9887171748 | G13: =Messy_Data!N13 -> suresh@company.com | H13: =Messy_Data!O13 -> 57006 | I13: =Messy_Data!P13 -> 40K-60K | O13: =Messy_Data!S13 -> M20 | P13: =Messy_Data!U13 -> ACTIVE | Q13: =Messy_Data!V13 -> 810 | R13: =Messy_Data!W13 -> 26 | S13: =Messy_Data!X13 -> 2 | AA13: =Messy_Data!AA13 -> OK
A14: =Messy_Data!B14 -> EMP13 | B14: =Messy_Data!D14 -> Suresh | C14: =Messy_Data!F14 -> HR | D14: =Messy_Data!H14 -> 44811 | E14: =Messy_Data!J14 -> 44964 | F14: =Messy_Data!L14 -> 9561915728 | G14: =Messy_Data!N14 -> ankit@company.com | H14: =Messy_Data!O14 -> 94507 | I14: =Messy_Data!P14 -> Above 80K | O14: =Messy_Data!S14 -> M24 | P14: =Messy_Data!U14 -> ON HOLD | Q14: =Messy_Data!V14 -> 153 | R14: =Messy_Data!W14 -> 5 | S14: =Messy_Data!X14 -> 0 | AA14: =Messy_Data!AA14 -> CHECK
... A301: =Messy_Data!B301 -> EMP300 | B301: =Messy_Data!D301 -> Ankit | C301: =Messy_Data!F301 -> SALES | D301: =Messy_Data!H301 -> 43888 | E301: =Messy_Data!J301 -> 44884 | F301: =Messy_Data!L301 -> 9346875401 | G301: =Messy_Data!N301 -> neha@company.com | H301: =Messy_Data!O301 -> 58738 | I301: =Messy_Data!P301 -> 40K-60K | O301: =Messy_Data!S301 -> M11 | P301: =Messy_Data!U301 -> ACTIVE | Q301: =Messy_Data!V301 -> 996 | R301: =Messy_Data!W301 -> 32 | S301: =Messy_Data!X301 -> 2 | AA301: =Messy_Data!AA301 -> OK

Sheet Pivote_Table
A2: Count of Emp ID Clean | B2: Status Clean | H2: Manager ID Clean | I2: Count of Emp ID Clean
A3: Department Clean | B3: ACTIVE | C3: RESIGNED | D3: Grand Total | H3: M1 | I3: 1
A4: FINANCE | C4: 1 | D4: 1 | H4: M2 | I4: 1
A5: SALES | B5: 1 | D5: 1 | H5: Grand Total | I5: 2
A6: Grand Total | B6: 1 | C6: 1 | D6: 2
D11: Department Clean | E11: Average of Experience Years
D12: FINANCE | E12: 4
D13: SALES | E13: 4
D14: Grand Total | E14: 4
A26: Department Clean | B26: Average of Salary
A27: FINANCE | B27: 62508
A28: SALES | B28: 71743 | D28: Salary Range | E28: Count of Emp ID Clean
A29: Grand Total | B29: 67125.5 | D29: 60K-80K | E29: 2
D30: Grand Total | E30: 2

Sheet Dasboard
AA9: 300
AA11: 105
AA12: 120
AA13: 75
